Workbook

Sheet Inc5000_Business_Analysis.xlsx
A1: _input | B1: _num | C1: _widgetName | D1: _source | E1: _resultNumber | F1: _pageUrl | G1: id | H1: rank | I1: workers | J1: company | K1: url | L1: state_l | M1: state_s | N1: city | O1: metro | P1: growth | Q1: revenue | R1: industry | S1: yrs_on_list
B2: 1 | C2: Inc5000 Company List | D2: Inc5000 Company List | E2: 1 | F2: http://www.inc.com/inc5000list/json/inc5000_2014.json | G2: 22890 | H2: 1 | I2: 227 | J2: Fuhu | K2: fuhu | L2: California | M2: CA | N2: El Segundo | O2: Los Angeles | P2: 158956.91 | Q2: 195640000 | R2: Consumer Products & Services | S2: 2
B3: 2 | C3: Inc5000 Company List | D3: Inc5000 Company List | E3: 2 | F3: http://www.inc.com/inc5000list/json/inc5000_2014.json | G3: 25747 | H3: 2 | I3: 191 | J3: Quest Nutrition | K3: quest-nutrition | L3: California | M3: CA | N3: El Segundo | O3: Los Angeles | P3: 57347.925 | Q3: 82640563 | R3: Food & Beverage | S3: 1
B4: 3 | C4: Inc5000 Company List | D4: Inc5000 Company List | E4: 3 | F4: http://www.inc.com/inc5000list/json/inc5000_2014.json | G4: 25643 | H4: 3 | I4: 145 | J4: Reliant Asset Management | K4: reliant-asset-management | L4: Virginia | M4: VA | N4: Arlington | O4: Washington DC | P4: 55460.165 | Q4: 85076502 | R4: Business Products & Services | S4: 1
B5: 4 | C5: Inc5000 Company List | D5: Inc5000 Company List | E5: 4 | F5: http://www.inc.com/inc5000list/json/inc5000_2014.json | G5: 26098 | H5: 4 | I5: 62 | J5: Superfish | K5: superfish | L5: California | M5: CA | N5: Palo Alto | O5: San Jose | P5: 26042.963 | Q5: 35293000 | R5: Software | S5: 1
B6: 5 | C6: Inc5000 Company List | D6: Inc5000 Company List | E6: 5 | F6: http://www.inc.com/inc5000list/json/inc5000_2014.json | G6: 26182 | H6: 5 | I6: 92 | J6: Acacia Communications | K6: acacia-communications | L6: Massachusetts | M6: MA | N6: Maynard | O6: Boston | P6: 20690.458 | Q6: 77652360 | R6: Telecommunications | S6: 1
B7: 6 | C7: Inc5000 Company List | D7: Inc5000 Company List | E7: 6 | F7: http://www.inc.com/inc5000list/json/inc5000_2014.json | G7: 22913 | H7: 6 | I7: 50 | J7: Provider Power | K7: provider-power | L7: Maine | M7: ME | N7: Auburn | O7: Lewiston-Auburn ME | P7: 19876.517 | Q7: 137977203 | R7: Energy | S7: 2
B8: 7 | C8: Inc5000 Company List | D8: Inc5000 Company List | E8: 7 | F8: http://www.inc.com/inc5000list/json/inc5000_2014.json | G8: 22937 | H8: 7 | I8: 129 | J8: Crescendo Bioscience | K8: crescendo-bioscience | L8: California | M8: CA | N8: South San Francisco | O8: San Francisco | P8: 18375.069 | Q8: 27308000 | R8: Health | S8: 2
B9: 8 | C9: Inc5000 Company List | D9: Inc5000 Company List | E9: 8 | F9: http://www.inc.com/inc5000list/json/inc5000_2014.json | G9: 25413 | H9: 8 | I9: 130 | J9: Plexus Worldwide | K9: plexus-worldwide | L9: Arizona | M9: AZ | N9: Scottsdale | O9: Phoenix | P9: 16457.653 | Q9: 159897088 | R9: Health | S9: 1
B10: 9 | C10: Inc5000 Company List | D10: Inc5000 Company List | E10: 9 | F10: http://www.inc.com/inc5000list/json/inc5000_2014.json | G10: 26079 | H10: 9 | I10: 264 | J10: Vacasa | K10: vacasa | L10: Oregon | M10: OR | N10: Portland | O10: Portland OR | P10: 16192.061 | Q10: 26263454 | R10: Travel & Hospitality | S10: 1
B11: 10 | C11: Inc5000 Company List | D11: Inc5000 Company List | E11: 10 | F11: http://www.inc.com/inc5000list/json/inc5000_2014.json | G11: 25861 | H11: 10 | I11: 11 | J11: Go Energies | K11: go-energies | L11: North Carolina | M11: NC | N11: Wilmington | O11: Wilmington NC | P11: 16006.801 | Q11: 32851754 | R11: Energy | S11: 1
B12: 11 | C12: Inc5000 Company List | D12: Inc5000 Company List | E12: 11 | F12: http://www.inc.com/inc5000list/json/inc5000_2014.json | G12: 25231 | H12: 11 | I12: 113 | J12: Minute Key | K12: minute-key | L12: Colorado | M12: CO | N12: Boulder | O12: Boulder CO | P12: 14588.345 | Q12: 15782039 | R12: Consumer Products & Services | S12: 1
B13: 12 | C13: Inc5000 Company List | D13: Inc5000 Company List | E13: 12 | F13: http://www.inc.com/inc5000list/json/inc5000_2014.json | G13: 26450 | H13: 12 | I13: 135 | J13: Sainstore | K13: sainstore | L13: Kansas | M13: KS | N13: Lenexa | O13: Waterloo-Cedar Falls IA | P13: 14086.513 | Q13: 19243863 | R13: Business Products & Services | S13: 1
... B118: 117 | C118: Inc5000 Company List | D118: Inc5000 Company List | E118: 117 | F118: http://www.inc.com/inc5000list/json/inc5000_2014.json | G118: 25855 | H118: 117 | I118: 458 | J118: hCentive | K118: hcentive | L118: Virginia | M118: VA | N118: Reston | O118: Washington DC | P118: 3214.4606 | Q118: 26493445 | R118: Health | S118: 1
B119: 118 | C119: Inc5000 Company List | D119: Inc5000 Company List | E119: 118 | F119: http://www.inc.com/inc5000list/json/inc5000_2014.json | G119: 22903 | H119: 118 | I119: 14 | J119: Intelligent Audit | K119: intelligent-audit | L119: New Jersey | M119: NJ | N119: Rochelle Park | P119: 3122.0588 | Q119: 318842114 | R119: Logistics & Transportation | S119: 2
B120: 119 | C120: Inc5000 Company List | D120: Inc5000 Company List | E120: 119 | F120: http://www.inc.com/inc5000list/json/inc5000_2014.json | G120: 26332 | H120: 119 | I120: 60 | J120: SimpliSafe Home Security | K120: simplisafe-home-security | L120: Massachusetts | M120: MA | N120: Cambridge | O120: Boston | P120: 3075.8406 | Q120: 38454825 | R120: Security | S120: 1
B121: 120 | C121: Inc5000 Company List | D121: Inc5000 Company List | E121: 120 | F121: http://www.inc.com/inc5000list/json/inc5000_2014.json | G121: 25436 | H121: 120 | I121: 43 | J121: Boxman Studios | K121: boxman-studios | L121: North Carolina | M121: NC | N121: Charlotte | O121: Charlotte | P121: 3074.0826 | Q121: 4322910 | R121: Business Products & Services | S121: 1
B122: 121 | C122: Inc5000 Company List | D122: Inc5000 Company List | E122: 121 | F122: http://www.inc.com/inc5000list/json/inc5000_2014.json | G122: 26277 | H122: 121 | I122: 30 | J122: SeatGeek | K122: seatgeek | L122: New York | M122: NY | N122: New York | O122: New York City | P122: 3039.1304 | Q122: 12274000 | R122: Consumer Products & Services | S122: 1
B123: 122 | C123: Inc5000 Company List | D123: Inc5000 Company List | E123: 122 | F123: http://www.inc.com/inc5000list/json/inc5000_2014.json | G123: 24847 | H123: 122 | I123: 23 | J123: Smashwords | K123: smashwords | L123: California | M123: CA | N123: Los Gatos | O123: San Jose | P123: 3018.5723 | Q123: 22037828 | R123: Media | S123: 1
B124: 123 | C124: Inc5000 Company List | D124: Inc5000 Company List | E124: 123 | F124: http://www.inc.com/inc5000list/json/inc5000_2014.json | G124: 21756 | H124: 123 | I124: 18 | J124: Securityhunter | K124: securityhunter | L124: Maryland | M124: MD | N124: Baltimore | O124: Baltimore | P124: 2998.3413 | Q124: 35931650 | R124: Government Services | S124: 3
B125: 124 | C125: Inc5000 Company List | D125: Inc5000 Company List | E125: 124 | F125: http://www.inc.com/inc5000list/json/inc5000_2014.json | G125: 21024 | H125: 124 | I125: 74 | J125: VRx | K125: vrx | L125: Utah | M125: UT | N125: Salt Lake City | O125: Salt Lake City | P125: 2987.2957 | Q125: 89554237 | R125: Health | S125: 3
B126: 125 | C126: Inc5000 Company List | D126: Inc5000 Company List | E126: 125 | F126: http://www.inc.com/inc5000list/json/inc5000_2014.json | G126: 25425 | H126: 125 | I126: 42 | J126: SmackTom.com | K126: smacktomcom | L126: Florida | M126: FL | N126: Miami | O126: Miami | P126: 2963.7255 | Q126: 3125000 | R126: Retail | S126: 1
B127: 126 | C127: Inc5000 Company List | D127: Inc5000 Company List | E127: 126 | F127: http://www.inc.com/inc5000list/json/inc5000_2014.json | G127: 25034 | H127: 126 | I127: 10 | J127: Virtual Fleet Supervisor | K127: virtual-fleet-supervisor | L127: Florida | M127: FL | N127: Oviedo | O127: Orlando FL | P127: 2948.8362 | Q127: 3526101 | R127: Software | S127: 1
B128: 127 | C128: Inc5000 Company List | D128: Inc5000 Company List | E128: 127 | F128: http://www.inc.com/inc5000list/json/inc5000_2014.json | G128: 25283 | H128: 127 | I128: 262 | J128: CareCloud | K128: carecloud | L128: Florida | M128: FL | N128: Miami | O128: Miami | P128: 2939.6153 | Q128: 10455000 | R128: Health | S128: 1
B129: 128 | C129: Inc5000 Company List | D129: Inc5000 Company List | E129: 128 | F129: http://www.inc.com/inc5000list/json/inc5000_2014.json | G129: 24789 | H129: 128 | I129: 64 | J129: Fueled | K129: fueled | L129: New York | M129: NY | N129: New York | O129: New York City | P129: 2916.7442 | Q129: 6486000 | R129: Advertising & Marketing | S129: 1
B130: 129 | C130: Inc5000 Company List | D130: Inc5000 Company List | E130: 129 | F130: http://www.inc.com/inc5000list/json/inc5000_2014.json | G130: 26484 | H130: 129 | I130: 14 | J130: Bob's Watches | K130: bobs-watches | L130: California | M130: CA | N130: Westminster | O130: Los Angeles | P130: 2861.191 | Q130: 11101120 | R130: Retail | S130: 1
B131: 130 | C131: Inc5000 Company List | D131: Inc5000 Company List | E131: 130 | F131: http://www.inc.com/inc5000list/json/inc5000_2014.json | G131: 24852 | H131: 130 | I131: 6 | J131: CPA Trend | K131: cpa-trend | L131: New York | M131: NY | N131: Howard Beach | O131: New York City | P131: 2842.941 | Q131: 5826876 | R131: Advertising & Marketing | S131: 1
... B136: 135 | C136: Inc5000 Company List | D136: Inc5000 Company List | E136: 135 | F136: http://www.inc.com/inc5000list/json/inc5000_2014.json | G136: 23162 | H136: 135 | I136: 24 | J136: Marketsmith | K136: marketsmith | L136: New Jersey | M136: NJ | N136: Parsippany | O136: New York City | P136: 2752.5555 | Q136: 72908666 | R136: Advertising & Marketing | S136: 2
B137: 136 | C137: Inc5000 Company List | D137: Inc5000 Company List | E137: 136 | F137: http://www.inc.com/inc5000list/json/inc5000_2014.json | G137: 25279 | H137: 136 | I137: 18 | J137: Project Management Academy | K137: project-management-academy | L137: Indiana | M137: IN | N137: West Lafayette | P137: 2752.4901 | Q137: 8094996 | R137: Education | S137: 1
B138: 137 | C138: Inc5000 Company List | D138: Inc5000 Company List | E138: 137 | F138: http://www.inc.com/inc5000list/json/inc5000_2014.json | G138: 24932 | H138: 137 | I138: 25 | J138: Flying Cork Media | K138: flying-cork-media | L138: Pennsylvania | M138: PA | N138: Pittsburgh | O138: Pittsburgh PA | P138: 2745.4166 | Q138: 7502709 | R138: Advertising & Marketing | S138: 1
B139: 138 | C139: Inc5000 Company List | D139: Inc5000 Company List | E139: 138 | F139: http://www.inc.com/inc5000list/json/inc5000_2014.json | G139: 24888 | H139: 138 | I139: 160 | J139: Motivity Labs | K139: motivity-labs | L139: Texas | M139: TX | N139: Irving | O139: Dallas | P139: 2716.0018 | Q139: 3225899 | R139: IT Services | S139: 1
B140: 139 | C140: Inc5000 Company List | D140: Inc5000 Company List | E140: 139 | F140: http://www.inc.com/inc5000list/json/inc5000_2014.json | G140: 26263 | H140: 139 | I140: 232 | J140: Twilio | K140: twilio | L140: California | M140: CA | N140: San Francisco | O140: San Francisco | P140: 2710.8696 | Q140: 51720000 | R140: Telecommunications | S140: 1
B141: 140 | C141: Inc5000 Company List | D141: Inc5000 Company List | E141: 140 | F141: http://www.inc.com/inc5000list/json/inc5000_2014.json | G141: 25095 | H141: 140 | I141: 20 | J141: Signature Closers | K141: signature-closers | L141: Ohio | M141: OH | N141: Upper Arlington | O141: Columbus OH | P141: 2709.3881 | Q141: 3843580 | R141: Real Estate | S141: 1
B142: 141 | C142: Inc5000 Company List | D142: Inc5000 Company List | E142: 141 | F142: http://www.inc.com/inc5000list/json/inc5000_2014.json | G142: 25749 | H142: 141 | I142: 81 | J142: PureCars | K142: purecars | L142: South Carolina | M142: SC | N142: Charleston | O142: Charleston-North Charleston SC | P142: 2689.9672 | Q142: 8725985 | R142: Advertising & Marketing | S142: 1
B143: 142 | C143: Inc5000 Company List | D143: Inc5000 Company List | E143: 142 | F143: http://www.inc.com/inc5000list/json/inc5000_2014.json | G143: 25236 | H143: 142 | I143: 96 | J143: The Cambridge Institute of International Education | K143: the-cambridge-institute-of-international-education | L143: Massachusetts | M143: MA | N143: Waltham | O143: Boston | P143: 2683.3172 | Q143: 9784000 | R143: Education | S143: 1
B144: 143 | C144: Inc5000 Company List | D144: Inc5000 Company List | E144: 143 | F144: http://www.inc.com/inc5000list/json/inc5000_2014.json | G144: 25237 | H144: 143 | I144: 53 | J144: Market6 | K144: market6 | L144: Illinois | M144: IL | N144: Deerfield | O144: Chicago | P144: 2677.1957 | Q144: 15085838 | R144: Software | S144: 1
B145: 144 | C145: Inc5000 Company List | D145: Inc5000 Company List | E145: 144 | F145: http://www.inc.com/inc5000list/json/inc5000_2014.json | G145: 25594 | H145: 144 | I145: 53 | J145: LiveRamp | K145: liveramp | L145: California | M145: CA | N145: San Francisco | O145: San Francisco | P145: 2665.2479 | Q145: 21040412 | R145: Advertising & Marketing | S145: 1
B146: 145 | C146: Inc5000 Company List | D146: Inc5000 Company List | E146: 145 | F146: http://www.inc.com/inc5000list/json/inc5000_2014.json | G146: 25620 | H146: 145 | I146: 160 | J146: MyClean | K146: myclean | L146: New York | M146: NY | N146: New York | O146: New York City | P146: 2646.4033 | Q146: 4399793 | R146: Consumer Products & Services | S146: 1
B147: 146 | C147: Inc5000 Company List | D147: Inc5000 Company List | E147: 146 | F147: http://www.inc.com/inc5000list/json/inc5000_2014.json | G147: 26220 | H147: 146 | I147: 35 | J147: PresenceLearning | K147: presencelearning | L147: California | M147: CA | N147: San Francisco | O147: San Francisco | P147: 2634.2593 | Q147: 5906000 | R147: Education | S147: 1
B148: 147 | C148: Inc5000 Company List | D148: Inc5000 Company List | E148: 147 | F148: http://www.inc.com/inc5000list/json/inc5000_2014.json | G148: 26517 | H148: 147 | I148: 140 | J148: Residential Capital Management | K148: residential-capital-management | L148: Georgia | M148: GA | N148: Atlanta | O148: Atlanta | P148: 2626.018 | Q148: 30167124 | R148: Real Estate | S148: 1
...

Sheet Clean Data
A1: _num | B1: _widgetName | C1: _source | D1: _resultNumber | E1: _pageUrl | F1: id | G1: rank | H1: workers | I1: Company Size | J1: company | K1: url | L1: state_l | M1: state_s | N1: city | O1: metro | P1: growth | Q1: revenue | R1: industry | S1: yrs_on_list
A2: 1 | B2: Inc5000 Company List | C2: Inc5000 Company List | D2: 1 | E2: http://www.inc.com/inc5000list/json/inc5000_2014.json | F2: 22890 | G2: 1 | H2: 227 | I2: =IF(H2<=50,"Small",IF(H2<=200,"Medium",IF(H2<=500,"Large","Enterprise"))) -> Large | J2: Fuhu | K2: fuhu | L2: California | M2: CA | N2: El Segundo | O2: Los Angeles | P2: 158956.91 | Q2: 195640000 | R2: Consumer Products & Services | S2: 2
A3: 2 | B3: Inc5000 Company List | C3: Inc5000 Company List | D3: 2 | E3: http://www.inc.com/inc5000list/json/inc5000_2014.json | F3: 25747 | G3: 2 | H3: 191 | I3: =IF(H3<=50,"Small",IF(H3<=200,"Medium",IF(H3<=500,"Large","Enterprise"))) -> Medium | J3: Quest Nutrition | K3: quest-nutrition | L3: California | M3: CA | N3: El Segundo | O3: Los Angeles | P3: 57347.925 | Q3: 82640563 | R3: Food & Beverage | S3: 1
A4: 3 | B4: Inc5000 Company List | C4: Inc5000 Company List | D4: 3 | E4: http://www.inc.com/inc5000list/json/inc5000_2014.json | F4: 25643 | G4: 3 | H4: 145 | I4: =IF(H4<=50,"Small",IF(H4<=200,"Medium",IF(H4<=500,"Large","Enterprise"))) -> Medium | J4: Reliant Asset Management | K4: reliant-asset-management | L4: Virginia | M4: VA | N4: Arlington | O4: Washington DC | P4: 55460.165 | Q4: 85076502 | R4: Business Products & Services | S4: 1
A5: 4 | B5: Inc5000 Company List | C5: Inc5000 Company List | D5: 4 | E5: http://www.inc.com/inc5000list/json/inc5000_2014.json | F5: 26098 | G5: 4 | H5: 62 | I5: =IF(H5<=50,"Small",IF(H5<=200,"Medium",IF(H5<=500,"Large","Enterprise"))) -> Medium | J5: Superfish | K5: superfish | L5: California | M5: CA | N5: Palo Alto | O5: San Jose | P5: 26042.963 | Q5: 35293000 | R5: Software | S5: 1
A6: 5 | B6: Inc5000 Company List | C6: Inc5000 Company List | D6: 5 | E6: http://www.inc.com/inc5000list/json/inc5000_2014.json | F6: 26182 | G6: 5 | H6: 92 | I6: =IF(H6<=50,"Small",IF(H6<=200,"Medium",IF(H6<=500,"Large","Enterprise"))) -> Medium | J6: Acacia Communications | K6: acacia-communications | L6: Massachusetts | M6: MA | N6: Maynard | O6: Boston | P6: 20690.458 | Q6: 77652360 | R6: Telecommunications | S6: 1
A7: 6 | B7: Inc5000 Company List | C7: Inc5000 Company List | D7: 6 | E7: http://www.inc.com/inc5000list/json/inc5000_2014.json | F7: 22913 | G7: 6 | H7: 50 | I7: =IF(H7<=50,"Small",IF(H7<=200,"Medium",IF(H7<=500,"Large","Enterprise"))) -> Small | J7: Provider Power | K7: provider-power | L7: Maine | M7: ME | N7: Auburn | O7: Lewiston-Auburn ME | P7: 19876.517 | Q7: 137977203 | R7: Energy | S7: 2
A8: 7 | B8: Inc5000 Company List | C8: Inc5000 Company List | D8: 7 | E8: http://www.inc.com/inc5000list/json/inc5000_2014.json | F8: 22937 | G8: 7 | H8: 129 | I8: =IF(H8<=50,"Small",IF(H8<=200,"Medium",IF(H8<=500,"Large","Enterprise"))) -> Medium | J8: Crescendo Bioscience | K8: crescendo-bioscience | L8: California | M8: CA | N8: South San Francisco | O8: San Francisco | P8: 18375.069 | Q8: 27308000 | R8: Health | S8: 2
A9: 8 | B9: Inc5000 Company List | C9: Inc5000 Company List | D9: 8 | E9: http://www.inc.com/inc5000list/json/inc5000_2014.json | F9: 25413 | G9: 8 | H9: 130 | I9: =IF(H9<=50,"Small",IF(H9<=200,"Medium",IF(H9<=500,"Large","Enterprise"))) -> Medium | J9: Plexus Worldwide | K9: plexus-worldwide | L9: Arizona | M9: AZ | N9: Scottsdale | O9: Phoenix | P9: 16457.653 | Q9: 159897088 | R9: Health | S9: 1
A10: 9 | B10: Inc5000 Company List | C10: Inc5000 Company List | D10: 9 | E10: http://www.inc.com/inc5000list/json/inc5000_2014.json | F10: 26079 | G10: 9 | H10: 264 | I10: =IF(H10<=50,"Small",IF(H10<=200,"Medium",IF(H10<=500,"Large","Enterprise"))) -> Large | J10: Vacasa | K10: vacasa | L10: Oregon | M10: OR | N10: Portland | O10: Portland OR | P10: 16192.061 | Q10: 26263454 | R10: Travel & Hospitality | S10: 1
A11: 10 | B11: Inc5000 Company List | C11: Inc5000 Company List | D11: 10 | E11: http://www.inc.com/inc5000list/json/inc5000_2014.json | F11: 25861 | G11: 10 | H11: 11 | I11: =IF(H11<=50,"Small",IF(H11<=200,"Medium",IF(H11<=500,"Large","Enterprise"))) -> Small | J11: Go Energies | K11: go-energies | L11: North Carolina | M11: NC | N11: Wilmington | O11: Wilmington NC | P11: 16006.801 | Q11: 32851754 | R11: Energy | S11: 1
A12: 11 | B12: Inc5000 Company List | C12: Inc5000 Company List | D12: 11 | E12: http://www.inc.com/inc5000list/json/inc5000_2014.json | F12: 25231 | G12: 11 | H12: 113 | I12: =IF(H12<=50,"Small",IF(H12<=200,"Medium",IF(H12<=500,"Large","Enterprise"))) -> Medium | J12: Minute Key | K12: minute-key | L12: Colorado | M12: CO | N12: Boulder | O12: Boulder CO | P12: 14588.345 | Q12: 15782039 | R12: Consumer Products & Services | S12: 1
A13: 12 | B13: Inc5000 Company List | C13: Inc5000 Company List | D13: 12 | E13: http://www.inc.com/inc5000list/json/inc5000_2014.json | F13: 26450 | G13: 12 | H13: 135 | I13: =IF(H13<=50,"Small",IF(H13<=200,"Medium",IF(H13<=500,"Large","Enterprise"))) -> Medium | J13: Sainstore | K13: sainstore | L13: Kansas | M13: KS | N13: Lenexa | O13: Waterloo-Cedar Falls IA | P13: 14086.513 | Q13: 19243863 | R13: Business Products & Services | S13: 1
... A118: 117 | B118: Inc5000 Company List | C118: Inc5000 Company List | D118: 117 | E118: http://www.inc.com/inc5000list/json/inc5000_2014.json | F118: 25855 | G118: 117 | H118: 458 | I118: =IF(H118<=50,"Small",IF(H118<=200,"Medium",IF(H118<=500,"Large","Enterprise"))) -> Large | J118: hCentive | K118: hcentive | L118: Virginia | M118: VA | N118: Reston | O118: Washington DC | P118: 3214.4606 | Q118: 26493445 | R118: Health | S118: 1
A119: 118 | B119: Inc5000 Company List | C119: Inc5000 Company List | D119: 118 | E119: http://www.inc.com/inc5000list/json/inc5000_2014.json | F119: 22903 | G119: 118 | H119: 14 | I119: =IF(H119<=50,"Small",IF(H119<=200,"Medium",IF(H119<=500,"Large","Enterprise"))) -> Small | J119: Intelligent Audit | K119: intelligent-audit | L119: New Jersey | M119: NJ | N119: Rochelle Park | P119: 3122.0588 | Q119: 318842114 | R119: Logistics & Transportation | S119: 2
A120: 119 | B120: Inc5000 Company List | C120: Inc5000 Company List | D120: 119 | E120: http://www.inc.com/inc5000list/json/inc5000_2014.json | F120: 26332 | G120: 119 | H120: 60 | I120: =IF(H120<=50,"Small",IF(H120<=200,"Medium",IF(H120<=500,"Large","Enterprise"))) -> Medium | J120: SimpliSafe Home Security | K120: simplisafe-home-security | L120: Massachusetts | M120: MA | N120: Cambridge | O120: Boston | P120: 3075.8406 | Q120: 38454825 | R120: Security | S120: 1
A121: 120 | B121: Inc5000 Company List | C121: Inc5000 Company List | D121: 120 | E121: http://www.inc.com/inc5000list/json/inc5000_2014.json | F121: 25436 | G121: 120 | H121: 43 | I121: =IF(H121<=50,"Small",IF(H121<=200,"Medium",IF(H121<=500,"Large","Enterprise"))) -> Small | J121: Boxman Studios | K121: boxman-studios | L121: North Carolina | M121: NC | N121: Charlotte | O121: Charlotte | P121: 3074.0826 | Q121: 4322910 | R121: Business Products & Services | S121: 1
A122: 121 | B122: Inc5000 Company List | C122: Inc5000 Company List | D122: 121 | E122: http://www.inc.com/inc5000list/json/inc5000_2014.json | F122: 26277 | G122: 121 | H122: 30 | I122: =IF(H122<=50,"Small",IF(H122<=200,"Medium",IF(H122<=500,"Large","Enterprise"))) -> Small | J122: SeatGeek | K122: seatgeek | L122: New York | M122: NY | N122: New York | O122: New York City | P122: 3039.1304 | Q122: 12274000 | R122: Consumer Products & Services | S122: 1
A123: 122 | B123: Inc5000 Company List | C123: Inc5000 Company List | D123: 122 | E123: http://www.inc.com/inc5000list/json/inc5000_2014.json | F123: 24847 | G123: 122 | H123: 23 | I123: =IF(H123<=50,"Small",IF(H123<=200,"Medium",IF(H123<=500,"Large","Enterprise"))) -> Small | J123: Smashwords | K123: smashwords | L123: California | M123: CA | N123: Los Gatos | O123: San Jose | P123: 3018.5723 | Q123: 22037828 | R123: Media | S123: 1
A124: 123 | B124: Inc5000 Company List | C124: Inc5000 Company List | D124: 123 | E124: http://www.inc.com/inc5000list/json/inc5000_2014.json | F124: 21756 | G124: 123 | H124: 18 | I124: =IF(H124<=50,"Small",IF(H124<=200,"Medium",IF(H124<=500,"Large","Enterprise"))) -> Small | J124: Securityhunter | K124: securityhunter | L124: Maryland | M124: MD | N124: Baltimore | O124: Baltimore | P124: 2998.3413 | Q124: 35931650 | R124: Government Services | S124: 3
A125: 124 | B125: Inc5000 Company List | C125: Inc5000 Company List | D125: 124 | E125: http://www.inc.com/inc5000list/json/inc5000_2014.json | F125: 21024 | G125: 124 | H125: 74 | I125: =IF(H125<=50,"Small",IF(H125<=200,"Medium",IF(H125<=500,"Large","Enterprise"))) -> Medium | J125: VRx | K125: vrx | L125: Utah | M125: UT | N125: Salt Lake City | O125: Salt Lake City | P125: 2987.2957 | Q125: 89554237 | R125: Health | S125: 3
A126: 125 | B126: Inc5000 Company List | C126: Inc5000 Company List | D126: 125 | E126: http://www.inc.com/inc5000list/json/inc5000_2014.json | F126: 25425 | G126: 125 | H126: 42 | I126: =IF(H126<=50,"Small",IF(H126<=200,"Medium",IF(H126<=500,"Large","Enterprise"))) -> Small | J126: SmackTom.com | K126: smacktomcom | L126: Florida | M126: FL | N126: Miami | O126: Miami | P126: 2963.7255 | Q126: 3125000 | R126: Retail | S126: 1
A127: 126 | B127: Inc5000 Company List | C127: Inc5000 Company List | D127: 126 | E127: http://www.inc.com/inc5000list/json/inc5000_2014.json | F127: 25034 | G127: 126 | H127: 10 | I127: =IF(H127<=50,"Small",IF(H127<=200,"Medium",IF(H127<=500,"Large","Enterprise"))) -> Small | J127: Virtual Fleet Supervisor | K127: virtual-fleet-supervisor | L127: Florida | M127: FL | N127: Oviedo | O127: Orlando FL | P127: 2948.8362 | Q127: 3526101 | R127: Software | S127: 1
A128: 127 | B128: Inc5000 Company List | C128: Inc5000 Company List | D128: 127 | E128: http://www.inc.com/inc5000list/json/inc5000_2014.json | F128: 25283 | G128: 127 | H128: 262 | I128: =IF(H128<=50,"Small",IF(H128<=200,"Medium",IF(H128<=500,"Large","Enterprise"))) -> Large | J128: CareCloud | K128: carecloud | L128: Florida | M128: FL | N128: Miami | O128: Miami | P128: 2939.6153 | Q128: 10455000 | R128: Health | S128: 1
A129: 128 | B129: Inc5000 Company List | C129: Inc5000 Company List | D129: 128 | E129: http://www.inc.com/inc5000list/json/inc5000_2014.json | F129: 24789 | G129: 128 | H129: 64 | I129: =IF(H129<=50,"Small",IF(H129<=200,"Medium",IF(H129<=500,"Large","Enterprise"))) -> Medium | J129: Fueled | K129: fueled | L129: New York | M129: NY | N129: New York | O129: New York City | P129: 2916.7442 | Q129: 6486000 | R129: Advertising & Marketing | S129: 1
A130: 129 | B130: Inc5000 Company List | C130: Inc5000 Company List | D130: 129 | E130: http://www.inc.com/inc5000list/json/inc5000_2014.json | F130: 26484 | G130: 129 | H130: 14 | I130: =IF(H130<=50,"Small",IF(H130<=200,"Medium",IF(H130<=500,"Large","Enterprise"))) -> Small | J130: Bob's Watches | K130: bobs-watches | L130: California | M130: CA | N130: Westminster | O130: Los Angeles | P130: 2861.191 | Q130: 11101120 | R130: Retail | S130: 1
A131: 130 | B131: Inc5000 Company List | C131: Inc5000 Company List | D131: 130 | E131: http://www.inc.com/inc5000list/json/inc5000_2014.json | F131: 24852 | G131: 130 | H131: 6 | I131: =IF(H131<=50,"Small",IF(H131<=200,"Medium",IF(H131<=500,"Large","Enterprise"))) -> Small | J131: CPA Trend | K131: cpa-trend | L131: New York | M131: NY | N131: Howard Beach | O131: New York City | P131: 2842.941 | Q131: 5826876 | R131: Advertising & Marketing | S131: 1
... A136: 135 | B136: Inc5000 Company List | C136: Inc5000 Company List | D136: 135 | E136: http://www.inc.com/inc5000list/json/inc5000_2014.json | F136: 23162 | G136: 135 | H136: 24 | I136: =IF(H136<=50,"Small",IF(H136<=200,"Medium",IF(H136<=500,"Large","Enterprise"))) -> Small | J136: Marketsmith | K136: marketsmith | L136: New Jersey | M136: NJ | N136: Parsippany | O136: New York City | P136: 2752.5555 | Q136: 72908666 | R136: Advertising & Marketing | S136: 2
A137: 136 | B137: Inc5000 Company List | C137: Inc5000 Company List | D137: 136 | E137: http://www.inc.com/inc5000list/json/inc5000_2014.json | F137: 25279 | G137: 136 | H137: 18 | I137: =IF(H137<=50,"Small",IF(H137<=200,"Medium",IF(H137<=500,"Large","Enterprise"))) -> Small | J137: Project Management Academy | K137: project-management-academy | L137: Indiana | M137: IN | N137: West Lafayette | P137: 2752.4901 | Q137: 8094996 | R137: Education | S137: 1
A138: 137 | B138: Inc5000 Company List | C138: Inc5000 Company List | D138: 137 | E138: http://www.inc.com/inc5000list/json/inc5000_2014.json | F138: 24932 | G138: 137 | H138: 25 | I138: =IF(H138<=50,"Small",IF(H138<=200,"Medium",IF(H138<=500,"Large","Enterprise"))) -> Small | J138: Flying Cork Media | K138: flying-cork-media | L138: Pennsylvania | M138: PA | N138: Pittsburgh | O138: Pittsburgh PA | P138: 2745.4166 | Q138: 7502709 | R138: Advertising & Marketing | S138: 1
A139: 138 | B139: Inc5000 Company List | C139: Inc5000 Company List | D139: 138 | E139: http://www.inc.com/inc5000list/json/inc5000_2014.json | F139: 24888 | G139: 138 | H139: 160 | I139: =IF(H139<=50,"Small",IF(H139<=200,"Medium",IF(H139<=500,"Large","Enterprise"))) -> Medium | J139: Motivity Labs | K139: motivity-labs | L139: Texas | M139: TX | N139: Irving | O139: Dallas | P139: 2716.0018 | Q139: 3225899 | R139: IT Services | S139: 1
A140: 139 | B140: Inc5000 Company List | C140: Inc5000 Company List | D140: 139 | E140: http://www.inc.com/inc5000list/json/inc5000_2014.json | F140: 26263 | G140: 139 | H140: 232 | I140: =IF(H140<=50,"Small",IF(H140<=200,"Medium",IF(H140<=500,"Large","Enterprise"))) -> Large | J140: Twilio | K140: twilio | L140: California | M140: CA | N140: San Francisco | O140: San Francisco | P140: 2710.8696 | Q140: 51720000 | R140: Telecommunications | S140: 1
A141: 140 | B141: Inc5000 Company List | C141: Inc5000 Company List | D141: 140 | E141: http://www.inc.com/inc5000list/json/inc5000_2014.json | F141: 25095 | G141: 140 | H141: 20 | I141: =IF(H141<=50,"Small",IF(H141<=200,"Medium",IF(H141<=500,"Large","Enterprise"))) -> Small | J141: Signature Closers | K141: signature-closers | L141: Ohio | M141: OH | N141: Upper Arlington | O141: Columbus OH | P141: 2709.3881 | Q141: 3843580 | R141: Real Estate | S141: 1
A142: 141 | B142: Inc5000 Company List | C142: Inc5000 Company List | D142: 141 | E142: http://www.inc.com/inc5000list/json/inc5000_2014.json | F142: 25749 | G142: 141 | H142: 81 | I142: =IF(H142<=50,"Small",IF(H142<=200,"Medium",IF(H142<=500,"Large","Enterprise"))) -> Medium | J142: PureCars | K142: purecars | L142: South Carolina | M142: SC | N142: Charleston | O142: Charleston-North Charleston SC | P142: 2689.9672 | Q142: 8725985 | R142: Advertising & Marketing | S142: 1
A143: 142 | B143: Inc5000 Company List | C143: Inc5000 Company List | D143: 142 | E143: http://www.inc.com/inc5000list/json/inc5000_2014.json | F143: 25236 | G143: 142 | H143: 96 | I143: =IF(H143<=50,"Small",IF(H143<=200,"Medium",IF(H143<=500,"Large","Enterprise"))) -> Medium | J143: The Cambridge Institute of International Education | K143: the-cambridge-institute-of-international-education | L143: Massachusetts | M143: MA | N143: Waltham | O143: Boston | P143: 2683.3172 | Q143: 9784000 | R143: Education | S143: 1
A144: 143 | B144: Inc5000 Company List | C144: Inc5000 Company List | D144: 143 | E144: http://www.inc.com/inc5000list/json/inc5000_2014.json | F144: 25237 | G144: 143 | H144: 53 | I144: =IF(H144<=50,"Small",IF(H144<=200,"Medium",IF(H144<=500,"Large","Enterprise"))) -> Medium | J144: Market6 | K144: market6 | L144: Illinois | M144: IL | N144: Deerfield | O144: Chicago | P144: 2677.1957 | Q144: 15085838 | R144: Software | S144: 1
A145: 144 | B145: Inc5000 Company List | C145: Inc5000 Company List | D145: 144 | E145: http://www.inc.com/inc5000list/json/inc5000_2014.json | F145: 25594 | G145: 144 | H145: 53 | I145: =IF(H145<=50,"Small",IF(H145<=200,"Medium",IF(H145<=500,"Large","Enterprise"))) -> Medium | J145: LiveRamp | K145: liveramp | L145: California | M145: CA | N145: San Francisco | O145: San Francisco | P145: 2665.2479 | Q145: 21040412 | R145: Advertising & Marketing | S145: 1
A146: 145 | B146: Inc5000 Company List | C146: Inc5000 Company List | D146: 145 | E146: http://www.inc.com/inc5000list/json/inc5000_2014.json | F146: 25620 | G146: 145 | H146: 160 | I146: =IF(H146<=50,"Small",IF(H146<=200,"Medium",IF(H146<=500,"Large","Enterprise"))) -> Medium | J146: MyClean | K146: myclean | L146: New York | M146: NY | N146: New York | O146: New York City | P146: 2646.4033 | Q146: 4399793 | R146: Consumer Products & Services | S146: 1
A147: 146 | B147: Inc5000 Company List | C147: Inc5000 Company List | D147: 146 | E147: http://www.inc.com/inc5000list/json/inc5000_2014.json | F147: 26220 | G147: 146 | H147: 35 | I147: =IF(H147<=50,"Small",IF(H147<=200,"Medium",IF(H147<=500,"Large","Enterprise"))) -> Small | J147: PresenceLearning | K147: presencelearning | L147: California | M147: CA | N147: San Francisco | O147: San Francisco | P147: 2634.2593 | Q147: 5906000 | R147: Education | S147: 1
A148: 147 | B148: Inc5000 Company List | C148: Inc5000 Company List | D148: 147 | E148: http://www.inc.com/inc5000list/json/inc5000_2014.json | F148: 26517 | G148: 147 | H148: 140 | I148: =IF(H148<=50,"Small",IF(H148<=200,"Medium",IF(H148<=500,"Large","Enterprise"))) -> Medium | J148: Residential Capital Management | K148: residential-capital-management | L148: Georgia | M148: GA | N148: Atlanta | O148: Atlanta | P148: 2626.018 | Q148: 30167124 | R148: Real Estate | S148: 1
...

Sheet Data Dictonary
B1: Company | C1: Rank | D1: Workers | E1: Revenue | F1: Growth | G1: Industry | H1: State | I1: City | J1: Metro | K1: Years on List | L1: id | M1: url

Sheet Data Quality
A1: Company | B1: =COUNTBLANK(Inc5000_Business_Analysis.xlsx!J2:J5001) -> 0 | F1: METRIC | G1: MIN | H1: MAX
A2: Rank | B2: =COUNTBLANK(Inc5000_Business_Analysis.xlsx!H2:H5001) -> 0 | F2: Revenue | G2: =MIN(Inc5000_Business_Analysis.xlsx!Q2:Q5001) -> 1953000 | H2: =MAX(Inc5000_Business_Analysis.xlsx!Q2:Q5001) -> 5528202691
A3: Workers | B3: =COUNTBLANK(Inc5000_Business_Analysis.xlsx!I2:I5001) -> 0 | F3: Growth | G3: =MIN(Inc5000_Business_Analysis.xlsx!P2:P5001) -> 42.447 | H3: =MAX(Inc5000_Business_Analysis.xlsx!P2:P5001) -> 158956.91
A4: Revenue | B4: =COUNTBLANK(Inc5000_Business_Analysis.xlsx!Q2:Q5001) -> 0 | F4: Workers | G4: =MIN(Inc5000_Business_Analysis.xlsx!I2:I5001) -> 0 | H4: =MAX(Inc5000_Business_Analysis.xlsx!I2:I5001) -> 34219
A5: Growth | B5: =COUNTBLANK(Inc5000_Business_Analysis.xlsx!P2:P5001) -> 0 | F5: Rank | G5: =MIN(Inc5000_Business_Analysis.xlsx!H2:H5001) -> 1 | H5: =MAX(Inc5000_Business_Analysis.xlsx!H2:H5001) -> 5000
A6: Industry | B6: =COUNTBLANK(Inc5000_Business_Analysis.xlsx!R2:R5001) -> 0 | F6: Years on List | G6: =MIN(Inc5000_Business_Analysis.xlsx!S2:S5001) -> 1 | H6: =MAX(Inc5000_Business_Analysis.xlsx!S2:S5001) -> 12
A7: State | B7: =COUNTBLANK(Inc5000_Business_Analysis.xlsx!L2:L5001) -> 0
A8: City | B8: =COUNTBLANK(Inc5000_Business_Analysis.xlsx!N2:N5001) -> 0
A9: Metro | B9: =COUNTBLANK(Inc5000_Business_Analysis.xlsx!O2:O5001) -> 58
A10: Years on List | B10: =COUNTBLANK(Inc5000_Business_Analysis.xlsx!S2:S5001) -> 0
A11: id | B11: =COUNTBLANK(Inc5000_Business_Analysis.xlsx!G2:G5001) -> 0
A12: url | B12: =COUNTBLANK(Inc5000_Business_Analysis.xlsx!K2:K5001) -> 0
A13: Total company record | B13: =COUNTA(Inc5000_Business_Analysis.xlsx!J2:J5001) -> 5000
A14: Unique company | B14: =COUNTA(_xlfn.UNIQUE(Inc5000_Business_Analysis.xlsx!J2:J5001)) -> 5000

Sheet Industry Analysis
A3: Row Labels | B3: Count of company | C3: Sum of revenue | D3: Average of growth | E3: Sum of workers | H3: RANK | I3: INDUSTRY | J3: AVERAGE GROWTH
A4: Health | B4: 377 | C4: 22022876049 | D4: 637.63296 | E4: 92487 | H4: 1 | I4: Consumer Products and services | J4: 1331.791
A5: Energy | B5: 116 | C5: 21602659306 | D5: 970.03526 | E5: 23981 | H5: 2 | I5: Energy | J5: 970.035
A6: IT Services | B6: 733 | C6: 19363587015 | D6: 347.70215 | E6: 111662 | H6: 3 | I6: Food and Beverage | J6: 963.035
A7: Business Products & Services | B7: 435 | C7: 17175083779 | D7: 439.66012 | E7: 116613 | H7: 4 | I7: Health | J7: 637.632
A8: Financial Services | B8: 278 | C8: 12212242543 | D8: 572.45437 | E8: 42727 | H8: 5 | I8: Government Services | J8: 594.71
A9: Human Resources | B9: 199 | C9: 12174441948 | D9: 224.28669 | E9: 171203
A10: Logistics & Transportation | B10: 132 | C10: 11208388344 | D10: 266.17062 | E10: 29020
A11: Consumer Products & Services | B11: 230 | C11: 10746810431 | D11: 1331.7911 | E11: 24391 | H11: Rank | I11: Industry | J11: Revenue
A12: Construction | B12: 198 | C12: 10342377737 | D12: 403.42456 | E12: 23575 | H12: 1 | I12: Health | J12: 22022876049
A13: Telecommunications | B13: 135 | C13: 9336973728 | D13: 438.28913 | E13: 38391 | H13: 2 | I13: Energy | J13: 21602659306
A14: Real Estate | B14: 131 | C14: 8886571850 | D14: 576.90383 | E14: 19608 | H14: 3 | I14: IT Services | J14: 19363587015
A15: Retail | B15: 200 | C15: 8361870250 | D15: 529.52237 | E15: 33732 | H15: 4 | I15: Business Products and Services | J15: 17175083779
A16: Manufacturing | B16: 212 | C16: 7466296462 | D16: 238.49666 | E16: 33777 | H16: 5 | I16: Financial Services | J16: 12212242543
A17: Advertising & Marketing | B17: 453 | C17: 7317073720 | D17: 519.89416 | E17: 27685
A18: Software | B18: 338 | C18: 7205033140 | D18: 557.1092 | E18: 44841
A19: Food & Beverage | B19: 132 | C19: 6481046076 | D19: 963.14185 | E19: 65423
A20: Government Services | B20: 212 | C20: 6345931528 | D20: 594.71026 | E20: 28278
A21: Insurance | B21: 67 | C21: 4550304954 | D21: 243.80811 | E21: 12698
A22: Travel & Hospitality | B22: 62 | C22: 3644726185 | D22: 547.30438 | E22: 22041
A23: Security | B23: 68 | C23: 3288637477 | D23: 484.52829 | E23: 53571
A24: Engineering | B24: 66 | C24: 1341559405 | D24: 424.52157 | E24: 8098
A25: Education | B25: 78 | C25: 1181235155 | D25: 367.44415 | E25: 6203
A26: Computer Hardware | B26: 34 | C26: 1149110342 | D26: 342.11667 | E26: 1970
A27: Media | B27: 60 | C27: 1097032891 | D27: 436.9344 | E27: 8651
A28: Environmental Services | B28: 54 | C28: 789041496 | D28: 223.88 | E28: 4223
A29: Grand Total | B29: 5000 | C29: 215290911811 | D29: 516.43989 | E29: 1044849
H33: Insight No | I33: Finding | J33: Business Impact
H34: 1 | I34: Consumer Products & Services has the highest average growth (1331.8%), but it is not among the top 5 revenue-generating industries. | J34: High-growth industries are not always the largest markets; they may represent emerging opportunities rather than mature revenue leaders.
A39: Average of growth | B39: Column Labels
A40: Row Labels | B40: Enterprise | C40: Large | D40: Medium | E40: Small | F40: Grand Total | H40: Rank | I40: Industry | J40: Company Size | K40: Average Growth
A41: Advertising & Marketing | B41: 178.87097 | C41: 572.56815 | D41: 576.82291 | E41: 490.7192 | F41: 519.89416 | H41: 1 | I41: Consumer Products & Services | J41: Large | K41: 13533.198
A42: Business Products & Services | B42: 132.45313 | C42: 250.20916 | D42: 821.32118 | E42: 289.85648 | F42: 439.66012 | H42: 2 | I42: Travel & Hospitality | J42: Large | K42: 2968.9968
A43: Computer Hardware | C43: 94.6381 | D43: 197.82744 | E43: 436.35236 | F43: 342.11667 | H43: 3 | I43: Food & Beverage | J43: Medium | K43: 1902.0848
A44: Construction | B44: 88.0979 | C44: 331.98259 | D44: 275.96714 | E44: 489.17619 | F44: 403.42456 | H44: 4 | I44: Energy | J44: Small | K44: 1478.2523
A45: Consumer Products & Services | B45: 544.04914 | C45: 13533.198 | D45: 813.18224 | E45: 603.12175 | F45: 1331.7911 | H45: 5 | I45: Consumer Products & Services | J45: Medium | K45: 813.18224
A46: Education | B46: 54.3511 | C46: 512.71215 | D46: 257.45046 | E46: 426.07923 | F46: 367.44415
A47: Energy | B47: 522.79601 | C47: 803.32554 | D47: 407.32432 | E47: 1478.2523 | F47: 970.03526
A48: Engineering | B48: 166.5972 | C48: 211.28214 | D48: 192.83634 | E48: 655.47457 | F48: 424.52157
A49: Environmental Services | C49: 185.21023 | D49: 127.90318 | E49: 328.33628 | F49: 223.88
...

Sheet Company Size Analysis
A3: Row Labels | B3: Count of company
A4: Enterprise | B4: 312
A5: Large | B5: 484
A6: Medium | B6: 1667
A7: Small | B7: 2537
A8: Grand Total | B8: 5000
B12: Company Size | C12: Median Growth
B13: Enterprise | C13: {=MEDIAN(_xlfn._xlws.FILTER('Clean Data'!$P$2:$P$5001,'Clean Data'!$T$2:$T$5001=F4))} -> 151.7228
B14: Large | C14: {=MEDIAN(_xlfn._xlws.FILTER('Clean Data'!$P$2:$P$5001,'Clean Data'!$H$2:$H$5001=F5))} -> 110.1436
B15: Medium | C15: {=MEDIAN(_xlfn._xlws.FILTER('Clean Data'!$P$2:$P$5001,'Clean Data'!$H$2:$H$5001=F6))} -> 110.1436
B16: Small | C16: {=MEDIAN(_xlfn._xlws.FILTER('Clean Data'!$P$2:$P$5001,'Clean Data'!$H$2:$H$5001=F7))} -> 110.1436
B19: INSIGHT | C19: Large companies have the highest average growth in the dataset, but the substantially lower median growth indicates that this result is strongly influenced by a small number of extreme high-growth companies

Sheet Geographical Analysis
A3: Row Labels | B3: Count of company | C3: Sum of revenue | D3: Average of growth | E3: Average Revenue per Company
A4: Tennessee | B4: 80 | C4: 8153943024 | D4: 267.61047 | E4: 1.0192429e+08
A5: Wisconsin | B5: 70 | C5: 7063487004 | D5: 442.69816 | E5: 1.0090696e+08 | H5: Rank | I5: State | J5: No of Companies | M5: Rank | N5: State | O5: Avg Growth(MIN 50 Companies)
A6: Texas | B6: 404 | C6: 27263931736 | D6: 440.92521 | E6: 67484980 | H6: 1 | I6: California | J6: 694 | M6: 1 | N6: California | O6: 876.19916
A7: Minnesota | B7: 94 | C7: 6085563921 | D7: 267.687 | E7: 64740042 | H7: 2 | I7: Texas | J7: 404 | M7: 2 | N7: Arizona | O7: 778.15829
A8: Ohio | B8: 171 | C8: 11051298826 | D8: 314.35538 | E8: 64627479 | H8: 3 | I8: New York | J8: 335 | M8: 3 | N8: Virginia | O8: 674.52999
A9: Michigan | B9: 130 | C9: 7687537169 | D9: 367.55038 | E9: 59134901 | H9: 4 | I9: Florida | J9: 303 | M9: 4 | N9: Oregon | O9: 655.851
A10: Illinois | B10: 238 | C10: 13548067258 | D10: 371.03295 | E10: 56924652 | H10: 5 | I10: Virginia | J10: 284 | M10: 5 | N10: Alambama | O10: 648.14198
A11: Indiana | B11: 73 | C11: 3766357059 | D11: 444.65107 | E11: 51593932
A12: Arizona | B12: 104 | C12: 4782485805 | D12: 778.15829 | E12: 45985440
A13: California | B13: 694 | C13: 31017385250 | D13: 876.19916 | E13: 44693639
A14: Massachusetts | B14: 174 | C14: 7714875801 | D14: 497.09161 | E14: 44338367 | H14: Rank | I14: State | J14: Average of Growth | M14: Rank | N14: State | O14: No of Companies | P14: Avg Revenue of companies
A15: Colorado | B15: 122 | C15: 5285063747 | D15: 448.49266 | E15: 43320195 | H15: 1 | I15: Hawaii | J15: 2769.0041 | M15: 1 | N15: Tennessee | O15: 80 | P15: 1.0192429e+08
A16: North Carolina | B16: 146 | C16: 5287506108 | D16: 475.1414 | E16: 36215795 | H16: 2 | I16: Maine | J16: 1694.7104 | M16: 2 | N16: Wisconsin | O16: 70 | P16: 1.0090696e+08
A17: Utah | B17: 86 | C17: 3030554373 | D17: 561.86936 | E17: 35239004 | H17: 3 | I17: California | J17: 876.19916 | M17: 3 | N17: Texas | O17: 404 | P17: 67484980
A18: New Jersey | B18: 164 | C18: 5695140251 | D18: 403.7072 | E18: 34726465 | H18: 4 | I18: New Mexico | J18: 817.8129 | M18: 4 | N18: Minnesota | O18: 94 | P18: 64740042
A19: New York | B19: 335 | C19: 11289216207 | D19: 489.09057 | E19: 33699153 | H19: 5 | I19: Arizona | J19: 778.15829 | M19: 5 | N19: Ohio | O19: 171 | P19: 64627479
A20: Virginia | B20: 284 | C20: 9475062257 | D20: 674.52999 | E20: 33362895
A21: Georgia | B21: 209 | C21: 6247240672 | D21: 280.79995 | E21: 29891104
A22: Florida | B22: 303 | C22: 9012608940 | D22: 567.55941 | E22: 29744584
A23: Missouri | B23: 72 | C23: 2120454513 | D23: 427.40732 | E23: 29450757
A24: Oregon | B24: 61 | C24: 1762495329 | D24: 655.85178 | E24: 28893366
A25: Pennsylvania | B25: 191 | C25: 5069151677 | D25: 375.4008 | E25: 26540061
A26: South Carolina | B26: 55 | C26: 1440588332 | D26: 308.49417 | E26: 26192515
A27: Maryland | B27: 121 | C27: 2748758987 | D27: 375.85813 | E27: 22717016
A28: Alabama | B28: 56 | C28: 1226129111 | D28: 648.14198 | E28: 21895163
A29: Washington | B29: 107 | C29: 1982437206 | D29: 336.53206 | E29: 18527451
A30: Grand Total | B30: 4544 | C30: 199807340563 | D30: 518.35787 | E30: 43971686

Sheet Key Findings
B1: Business Question | C1: Finding | D1: Evidence | E1: Implication
A2: 1 | B2: Which industries grow fastest? | C2: High growth and high revenue scale do not necessarily occur in the same industries. Consumer Products & Services has the highest average growth, while Health leads in total revenue. | D2: Consumer Products & Services: 1,331.79% average growth. Health: $2.203B total revenue and 637.63% average growth. | E2: Businesses evaluating expansion opportunities should distinguish between emerging high-growth segments and established high-revenue segments rather than using growth alone as the decision criterion.
A3: 2 | B3: Does company size relate to growth? | C3: Large companies have the highest average growth, but the difference between average and median growth indicates that extreme observations strongly influence the averages. | D3: Large companies: 706.90% average growth vs 110.14% median growth. Enterprise companies: 275.85% average vs 151.72% median. | E3: Growth comparisons should consider both average and median values to avoid making decisions based on unusually high-growth companies.
A4: 3 | B4: Where are high-growth companies concentrated? | C4: California combines the largest concentration of companies with the highest average growth among states containing at least 50 companies. | D4: California has 694 companies and 876.20% average growth. Arizona ranks second with 104 companies and 778.16% average growth. | E4: California represents a strong combination of market scale and growth, while smaller states should be evaluated cautiously because their averages can be affected by small sample sizes.
A5: 4 | B5: Which states have the highest average revenue per company? | C5: States with the largest number of companies are not necessarily the states with the highest average revenue per company. | D5: Tennessee: $101.92M average revenue/company with 80 companies. Wisconsin: $100.91M with 70 companies. Texas: $67.48M with 404 companies. | E5: Market attractiveness should be evaluated using both company concentration and revenue efficiency rather than company count alone.
A6: 5 | B6: How representative is the average growth rate? | C6: The overall growth distribution is highly skewed, with extreme-growth companies substantially increasing the average growth rate. | D6: Median growth is 151.72% versus average growth of 516.44%. 82.14% of companies have growth of 500% or less, while only 17.86% exceed 500%. | E6: Median growth should be considered alongside average growth when evaluating typical company performance, as the average alone may overstate the experience of most companies.
A7: 6 | B7: What factors are associated with revenue? | C7: Revenue has a weak positive relationship with workforce size and a very weak relationship with years on the list, while growth has virtually no linear relationship with revenue. | D7: Revenue vs Workers correlation: 0.266; Revenue vs Years on List: 0.151; Revenue vs Growth: 0.002. | E7: Revenue should not be predicted from growth rate alone. Workforce size shows a somewhat stronger association with revenue, but other business factors likely explain much of the variation.
A8: 7 | B8: How concentrated is company growth? | C8: Most companies have moderate growth, while a smaller group of companies records exceptionally high growth. This indicates that the overall average growth is influenced by a relatively small number of high-growth companies. | D8: 1,646 companies (32.92%) have growth ≤100%, while 2,461 companies (49.22%) fall between 100% and 500%. Only 424 companies (8.48%) are between 500% and 1,000%, and 469 companies (9.38%) exceed 1,000%. Therefore, 82.14% of companies have growth below 500%, while only 17.86% exceed 500%. | E8: Management should use median growth and growth distribution alongside average growth when evaluating business performance, because the average can be disproportionately affected by a smaller number of extremely high-growth companies.

Sheet Growth Analysis
A1: Growth Band | B1: Company Count | C1: % of Companies
A2: ≤100% | B2: =COUNTIF('Clean Data'!$P$2:$P$5001,"<=100") -> 1646 | C2: =B2/$B$6 -> 0.3292
A3: 100–500% | B3: =COUNTIFS('Clean Data'!$P$2:$P$5001,">100",'Clean Data'!$P$2:$P$5001,"<=500") -> 2461 | C3: =B3/$B$6 -> 0.4922
A4: 500–1,000% | B4: =COUNTIFS('Clean Data'!$P$2:$P$5001,">500",'Clean Data'!$P$2:$P$5001,"<=1000") -> 424 | C4: =B4/$B$6 -> 0.0848
A5: >1,000% | B5: =COUNTIF('Clean Data'!$P$2:$P$5001,">1000") -> 469 | C5: =B5/$B$6 -> 0.0938
A6: Total | B6: =SUM(B2:B5) -> 5000 | C6: =SUM(C2:C5) -> 1
A8: Overall Median Growth | B8: =MEDIAN('Clean Data'!$P$2:$P$5001) -> 151.7228
A9: Overall Average Growth | B9: =AVERAGE('Clean Data'!$P$2:$P$5001) -> 516.43989
A11: =SUM(C4:C5) -> 0.1786
A13: INSIGHT | B13: Most companies (82.1%) have growth below 500%, while 17.9% exceed 500%, indicating that the very high overall average growth is influenced by a smaller group of high-growth companies.

Sheet Relationship Analysis
A1: Relationship | B1: Correlation | C1: Interpretation
A2: Revenue vs Workers | B2: =CORREL('Clean Data'!$Q$2:$Q$5001,'Clean Data'!$H$2:$H$5001) -> 0.26569902 | C2: Weak-to-moderate positive relationship
A3: Revenue vs Growth | B3: =CORREL('Clean Data'!$Q$2:$Q$5001,'Clean Data'!$P$2:$P$5001) -> 0.0017154375 | C3: Essentially no linear relationship
A4: Revenue vs Years on List | B4: =CORREL('Clean Data'!$Q$2:$Q$5001,'Clean Data'!$S$2:$S$5001) -> 0.15052295 | C4: Very weak positive relationship

Sheet Dashboard
A1: Inc. 5000 Business Performance Dashboard
A3: Total Companies | D3: Total Revenue | G3: Average Growth | J3: Median Growth | M3: Average Workers
A4: =COUNTA('Clean Data'!$J$2:$J$5001) -> 5000 | D4: =SUM('Clean Data'!$Q$2:$Q$5001) -> 215290911811 | G4: =AVERAGE('Clean Data'!$P$2:$P$5001) -> 516.43989 | J4: =MEDIAN('Clean Data'!$P$2:$P$5001) -> 151.7228 | M4: =AVERAGE('Clean Data'!$H$2:$H$5001) -> 208.9698

Sheet SQL Insights
A1: Analysis | B1: Business Question | C1: Key Finding | D1: Business Implication
A2: Industry Performance | B2: Which industries combine revenue scale, company presence and growth? | C2: Health leads total revenue, while Energy has nearly similar revenue with much higher average growth. | D2: Evaluate industries using both scale and growth.
A3: Company Size Performance | B3: Does company size relate to revenue and growth? | C3: Enterprise companies generate the most revenue, while Large companies have the highest average growth. | D3: Revenue scale and growth should be evaluated separately
A4: Geographic Opportunity | B4: Which states combine company concentration, revenue scale and growth? | C4: California combines the highest company concentration and total revenue with very high average growth. | D4: Evaluate geographic opportunities using both scale and growth.
A5: Growth Segmentation | B5: How is company growth distributed? | C5: 82.14% of companies have growth ≤500%, while 17.86% exceed 500%. | D5: Use median and distribution alongside average growth.
A6: High Revenue + High Growth | B6: Which companies combine substantial revenue scale with rapid growth? | C6: Only one company meets the $1B revenue and 500% growth thresholds. | D6: Companies achieving both substantial scale and extreme growth are uncommon.
A7: Company Ranking by Industry | B7: Which companies are the leading revenue performers within their respective industries? | C7: SQL ranking identified the top 3 revenue companies within each of the 25 industries. | D7: Industry-specific benchmarking can identify leading companies without comparing firms across fundamentally different markets.
A8: Growth Leaders Within Industry | B8: Which companies are the highest-growth performers within their respective industries? | C8: SQL ranking identifies the top 3 growth companies within each industry, enabling industry-specific benchmarking. | D8: Growth leaders should be compared against their industry peers rather than only against the overall market.
A9: Industry × Company Size | B9: Which industry and company-size combinations show the strongest growth? | C9: Growth varies substantially across industry-size combinations, with Energy–Small companies showing the highest average growth among combinations with at least 50 companies | D9: Company size should not be evaluated independently of industry when assessing growth performance.
A10: Industry Opportunity Scorecard | B10: Which industries combine strong growth, revenue scale, and sufficient market presence? | C10: Industries can be segmented into opportunity categories by evaluating average growth, total revenue, and company count together rather than relying on a single metric. | D10: Businesses can prioritize industries that demonstrate both market scale and growth potential, while avoiding decisions based solely on high growth or high revenue.
A11: Industry Opportunity Scorecard | B11: Which industries combine strong growth, revenue scale, and sufficient market presence? | C11: Consumer Products & Services and Energy are classified as High Opportunity, combining strong average growth with substantial revenue and company presence. Consumer Products & Services shows 1,331.79% average growth, while Energy shows 970.04%. | D11: Industries should be prioritized using a combination of growth, revenue scale, and market presence, rather than relying on a single performance metric.
